Workbook

Sheet Notas
A1: Producto Bruto Geográfico de Mendoza, 1970-2022
A3: Fuente original | B3: DEIE Mendoza — planilla 'PBG_1970-2022_variacionytasa_DEIE.xls'.
A4: Tramos | B4: Los datos se publicaron en 4 tramos, cada uno a precios constantes de un año base distinto:
A5: 1970-1985 | B5: A valores constantes de 1970, en Australes.
A6: 1986-1993 | B6: En pesos de 1996 (año base 1996, según la propia planilla de la DEIE).
A7: 1991-2003 | B7: En miles de pesos de 1993.
A8: 2004-2022 | B8: En miles de pesos de 1993 (también existe una versión a precios corrientes, hoja aparte).
A9: Empalme B->C | B9: Los tramos 1986-1993 y 1991-2003 SÍ se solapan en 1991-1993. Se usó el coeficiente de 1993 (año base del tramo largo) para reexpresar 1986-1990 en miles de pesos de 1993, y luego toda la serie 1986-2022 se llevó a precios de 1999 con el IPC.
A10: 1970-1985: SIN empalmar | B10: No hay año de solapamiento entre este tramo y 1986-1993. Se probó usar la tabla oficial de conversión monetaria (1 Peso = 10.000 Australes) junto con el IPC para reexpresarlo a precios de 1999, pero el resultado da un salto de nivel de ~30.000 veces respecto al tramo siguiente — señal de que el cambio de año base implica un recálculo metodológico (ponderadores sectoriales), no solo un cambio de moneda y precios. Por eso se decidió NO forzar una continuidad: 1970-1985 se deja como índice propio (base 1970=100, hoja 'PBG índice 1970-1985'), sin convertir a pesos ni empalmar con el resto de la serie.
A11: Respaldo de este criterio | B11: La propia DEIE, en su nota metodológica sobre el PBG (2019), recomienda evitar comparar valores absolutos del PBG entre años base distintos, ya que la discrepancia al cambiar de base es esperable y no un error de medición.
A12: Quiebre 2003-2004 | B12: La DEIE documenta que tampoco hay empalme formal entre las mediciones 1991-2003 y 2004-2022 (cambio metodológico). Se dejaron como continuas dentro del tramo 1986-2022 por ser la única fuente disponible; el salto de +16,4% en 2004 refleja ese quiebre, no un error de cálculo.

Sheet PBG por tramo
A1: Producto Bruto Geográfico de Mendoza — series por tramo de publicación
A2: Fuente: DEIE Mendoza. Cada tramo está a precios constantes del año base indicado (ver hoja Notas).
A4: Año | B4: Tramo | C4: Moneda / unidad | D4: Precios constantes de | E4: PBG | F4: Variación anual (%)
A5: 1970 | B5: 1970-1985 | C5: Australes | D5: 1970 | E5: 313.43
A6: 1971 | B6: 1970-1985 | C6: Australes | D6: 1970 | E6: 334.41 | F6: =E6/E5-1 -> 0.066936796
A7: 1972 | B7: 1970-1985 | C7: Australes | D7: 1970 | E7: 356.26 | F7: =E7/E6-1 -> 0.065338955
A8: 1973 | B8: 1970-1985 | C8: Australes | D8: 1970 | E8: 364.33 | F8: =E8/E7-1 -> 0.022651996
A9: 1974 | B9: 1970-1985 | C9: Australes | D9: 1970 | E9: 406.37 | F9: =E9/E8-1 -> 0.11538989
A10: 1975 | B10: 1970-1985 | C10: Australes | D10: 1970 | E10: 355.2 | F10: =E10/E9-1 -> -0.12591973
A11: 1976 | B11: 1970-1985 | C11: Australes | D11: 1970 | E11: 404.05 | F11: =E11/E10-1 -> 0.13752815
A12: 1977 | B12: 1970-1985 | C12: Australes | D12: 1970 | E12: 380.63 | F12: =E12/E11-1 -> -0.057963123
A13: 1978 | B13: 1970-1985 | C13: Australes | D13: 1970 | E13: 423.6 | F13: =E13/E12-1 -> 0.11289178
A14: 1979 | B14: 1970-1985 | C14: Australes | D14: 1970 | E14: 481.05 | F14: =E14/E13-1 -> 0.13562323
A15: 1980 | B15: 1970-1985 | C15: Australes | D15: 1970 | E15: 429.24 | F15: =E15/E14-1 -> -0.1077019
A16: 1981 | B16: 1970-1985 | C16: Australes | D16: 1970 | E16: 351.83 | F16: =E16/E15-1 -> -0.180342
A17: 1982 | B17: 1970-1985 | C17: Australes | D17: 1970 | E17: 360.43 | F17: =E17/E16-1 -> 0.024443623
... A20: 1985 | B20: 1970-1985 | C20: Australes | D20: 1970 | E20: 384.61 | F20: =E20/E19-1 -> -0.049030759
A22: 1986 | B22: 1986-1993 | C22: Pesos | D22: 1996 | E22: 267608.7
A23: 1987 | B23: 1986-1993 | C23: Pesos | D23: 1996 | E23: 271052 | F23: =E23/E22-1 -> 0.012866921
A24: 1988 | B24: 1986-1993 | C24: Pesos | D24: 1996 | E24: 264473 | F24: =E24/E23-1 -> -0.024272095
A25: 1989 | B25: 1986-1993 | C25: Pesos | D25: 1996 | E25: 253410 | F25: =E25/E24-1 -> -0.041830357
A26: 1990 | B26: 1986-1993 | C26: Pesos | D26: 1996 | E26: 253627 | F26: =E26/E25-1 -> 0.0008563198
A27: 1991 | B27: 1986-1993 | C27: Pesos | D27: 1996 | E27: 259579 | F27: =E27/E26-1 -> 0.023467533
A28: 1992 | B28: 1986-1993 | C28: Pesos | D28: 1996 | E28: 277469 | F28: =E28/E27-1 -> 0.068919289
A29: 1993 | B29: 1986-1993 | C29: Pesos | D29: 1996 | E29: 296965 | F29: =E29/E28-1 -> 0.070263705
A31: 1991 | B31: 1991-2003 | C31: Miles de pesos | D31: 1993 | E31: 6485506.9
A32: 1992 | B32: 1991-2003 | C32: Miles de pesos | D32: 1993 | E32: 7035025.6 | F32: =E32/E31-1 -> 0.084730252
A33: 1993 | B33: 1991-2003 | C33: Miles de pesos | D33: 1993 | E33: 7761508.2 | F33: =E33/E32-1 -> 0.10326652
A34: 1994 | B34: 1991-2003 | C34: Miles de pesos | D34: 1993 | E34: 8098028.3 | F34: =E34/E33-1 -> 0.043357564
A35: 1995 | B35: 1991-2003 | C35: Miles de pesos | D35: 1993 | E35: 7908811.4 | F35: =E35/E34-1 -> -0.023365802
A36: 1996 | B36: 1991-2003 | C36: Miles de pesos | D36: 1993 | E36: 8135361.9 | F36: =E36/E35-1 -> 0.028645327
A37: 1997 | B37: 1991-2003 | C37: Miles de pesos | D37: 1993 | E37: 8905959.4 | F37: =E37/E36-1 -> 0.094721978
A38: 1998 | B38: 1991-2003 | C38: Miles de pesos | D38: 1993 | E38: 9488295.9 | F38: =E38/E37-1 -> 0.065387283
A39: 1999 | B39: 1991-2003 | C39: Miles de pesos | D39: 1993 | E39: 9252615.2 | F39: =E39/E38-1 -> -0.024839103
A40: 2000 | B40: 1991-2003 | C40: Miles de pesos | D40: 1993 | E40: 9002038.5 | F40: =E40/E39-1 -> -0.027081718
A41: 2001 | B41: 1991-2003 | C41: Miles de pesos | D41: 1993 | E41: 8322993.5 | F41: =E41/E40-1 -> -0.075432354
A42: 2002 | B42: 1991-2003 | C42: Miles de pesos | D42: 1993 | E42: 7772198 | F42: =E42/E41-1 -> -0.066177567
A43: 2003 | B43: 1991-2003 | C43: Miles de pesos | D43: 1993 | E43: 9339929.6 | F43: =E43/E42-1 -> 0.20171019
A45: 2004 | B45: 2004-2022 | C45: Miles de pesos | D45: 1993 | E45: 10874929
A46: 2005 | B46: 2004-2022 | C46: Miles de pesos | D46: 1993 | E46: 11380763 | F46: =E46/E45-1 -> 0.046513803
...

Sheet PBG nominal 2004-2022
A1: PBG Mendoza a precios corrientes, 2004-2022
A2: Fuente: DEIE Mendoza. Valores nominales (sin ajustar por inflación).
A4: Año | B4: PBG (miles $ corrientes) | C4: Variación anual (%)
A5: 2004 | B5: 18742165
A6: 2005 | B6: 21705292 | C6: =B6/B5-1 -> 0.15809952
A7: 2006 | B7: 25989781 | C7: =B7/B6-1 -> 0.19739372
A8: 2007 | B8: 31491831 | C8: =B8/B7-1 -> 0.21170052
A9: 2008 | B9: 38997292 | C9: =B9/B8-1 -> 0.2383304
A10: 2009 | B10: 42718111 | C10: =B10/B9-1 -> 0.095412257
A11: 2010 | B11: 53282204 | C11: =B11/B10-1 -> 0.24729776
A12: 2011 | B12: 66868626 | C12: =B12/B11-1 -> 0.25498986
A13: 2012 | B13: 80942511 | C13: =B13/B12-1 -> 0.21047067
A14: 2013 | B14: 1.0185598e+08 | C14: =B14/B13-1 -> 0.25837442
A15: 2014 | B15: 1.3218945e+08 | C15: =B15/B14-1 -> 0.29780735
A16: 2015 | B16: 1.6619535e+08 | C16: =B16/B15-1 -> 0.25725125
A17: 2016 | B17: 2.2250952e+08 | C17: =B17/B16-1 -> 0.33884325
... A23: 2022 | B23: 2.2090503e+09 | C23: =B23/B22-1 -> 0.89439111

Sheet IPC INDEC
A1: IPC INDEC — Nivel general, base 1999=100
A3: Año | B3: IPC (base 1999=100)
A4: 1970 | B4: 4.7536083e-10
A5: 1971 | B5: 6.4042e-10
A6: 1972 | B6: 1.0147767e-09
A7: 1973 | B7: 1.6267208e-09
A8: 1974 | B8: 2.0206542e-09
A9: 1975 | B9: 5.7142667e-09
A10: 1976 | B10: 3.10863e-08
A11: 1977 | B11: 8.580805e-08
A12: 1978 | B12: 2.3640875e-07
A13: 1979 | B13: 6.1350683e-07
A14: 1980 | B14: 1.231702e-06
A15: 1981 | B15: 2.51855e-06
... A55: 2021 | B55: 8136.2593

Sheet Coeficiente de empalme (B-C)
A1: Coeficiente de empalme 1986-1993 -> 1991-2003
A3: Usa el solapamiento real 1991-1993 (ancla en 1993, año base del tramo largo).
A5: Coef_B | B5: ='PBG por tramo'!E33/'PBG por tramo'!E29 -> 26.136104
A7: Factor de reexpresión a precios de 1999 (IPC INDEC)
A8: Factor_1999 | B8: ='IPC INDEC'!B33/'IPC INDEC'!B27 -> 1.0815815
A10: Nota
A11: El tramo 1970-1985 NO se empalma con este: no hay año de solapamiento con 1986-1993, y se comprobó que usar la tabla de conversión monetaria (Austral->Peso) junto con el IPC da un salto de nivel de ~30.000 veces, incompatible con la evolución real observada. Ver hoja 'PBG índice 1970-1985'.

Sheet PBG índice 1970-1985
A1: PBG Mendoza, 1970-1985 — índice propio (1970=100)
A2: NO comparable en nivel con el tramo 1986-2022 (distinto año base, sin año de solapamiento).
A4: Año | B4: PBG (Australes de 1970) | C4: Índice (1970=100)
A5: 1970 | B5: ='PBG por tramo'!E5 -> 313.43 | C5: =B5/B$5*100 -> 100
A6: 1971 | B6: ='PBG por tramo'!E6 -> 334.41 | C6: =B6/B$5*100 -> 106.69368
A7: 1972 | B7: ='PBG por tramo'!E7 -> 356.26 | C7: =B7/B$5*100 -> 113.66493
A8: 1973 | B8: ='PBG por tramo'!E8 -> 364.33 | C8: =B8/B$5*100 -> 116.23967
A9: 1974 | B9: ='PBG por tramo'!E9 -> 406.37 | C9: =B9/B$5*100 -> 129.65255
A10: 1975 | B10: ='PBG por tramo'!E10 -> 355.2 | C10: =B10/B$5*100 -> 113.32674
A11: 1976 | B11: ='PBG por tramo'!E11 -> 404.05 | C11: =B11/B$5*100 -> 128.91236
A12: 1977 | B12: ='PBG por tramo'!E12 -> 380.63 | C12: =B12/B$5*100 -> 121.44019
A13: 1978 | B13: ='PBG por tramo'!E13 -> 423.6 | C13: =B13/B$5*100 -> 135.14979
A14: 1979 | B14: ='PBG por tramo'!E14 -> 481.05 | C14: =B14/B$5*100 -> 153.47925
A15: 1980 | B15: ='PBG por tramo'!E15 -> 429.24 | C15: =B15/B$5*100 -> 136.94924
A16: 1981 | B16: ='PBG por tramo'!E16 -> 351.83 | C16: =B16/B$5*100 -> 112.25154
... A20: 1985 | B20: ='PBG por tramo'!E20 -> 384.61 | C20: =B20/B$5*100 -> 122.71001

Sheet PBG a precios de 1999
A1: PBG Mendoza, 1986-2022 — a precios constantes de 1999
A2: PBG por tramo, reescalado con Coef_B, x Factor_1999. No incluye 1970-1985 (ver hoja aparte).
A4: Año | B4: Tramo de origen | C4: PBG (miles $ ctes. de 1999) | D4: Variación anual (%)
A5: 1986 | B5: B | C5: ='PBG por tramo'!E22*'Coeficiente de empalme (B-C)'!$B$5*'Coeficiente de empalme (B-C)'!$B$8 -> 7564850.3
A6: 1987 | B6: B | C6: ='PBG por tramo'!E23*'Coeficiente de empalme (B-C)'!$B$5*'Coeficiente de empalme (B-C)'!$B$8 -> 7662186.7 | D6: =C6/C5-1 -> 0.012866921
A7: 1988 | B7: B | C7: ='PBG por tramo'!E24*'Coeficiente de empalme (B-C)'!$B$5*'Coeficiente de empalme (B-C)'!$B$8 -> 7476209.3 | D7: =C7/C6-1 -> -0.024272095
A8: 1989 | B8: B | C8: ='PBG por tramo'!E25*'Coeficiente de empalme (B-C)'!$B$5*'Coeficiente de empalme (B-C)'!$B$8 -> 7163476.8 | D8: =C8/C7-1 -> -0.041830357
A9: 1990 | B9: B | C9: ='PBG por tramo'!E26*'Coeficiente de empalme (B-C)'!$B$5*'Coeficiente de empalme (B-C)'!$B$8 -> 7169611.1 | D9: =C9/C8-1 -> 0.0008563198
A10: 1991 | B10: C | C10: ='PBG por tramo'!E31*'Coeficiente de empalme (B-C)'!$B$8 -> 7014604.4 | D10: =C10/C9-1 -> -0.021619949
A11: 1992 | B11: C | C11: ='PBG por tramo'!E32*'Coeficiente de empalme (B-C)'!$B$8 -> 7608953.6 | D11: =C11/C10-1 -> 0.084730252
A12: 1993 | B12: C | C12: ='PBG por tramo'!E33*'Coeficiente de empalme (B-C)'!$B$8 -> 8394703.8 | D12: =C12/C11-1 -> 0.10326652
A13: 1994 | B13: C | C13: ='PBG por tramo'!E34*'Coeficiente de empalme (B-C)'!$B$8 -> 8758677.7 | D13: =C13/C12-1 -> 0.043357564
A14: 1995 | B14: C | C14: ='PBG por tramo'!E35*'Coeficiente de empalme (B-C)'!$B$8 -> 8554024.2 | D14: =C14/C13-1 -> -0.023365802
A15: 1996 | B15: C | C15: ='PBG por tramo'!E36*'Coeficiente de empalme (B-C)'!$B$8 -> 8799057 | D15: =C15/C14-1 -> 0.028645327
A16: 1997 | B16: C | C16: ='PBG por tramo'!E37*'Coeficiente de empalme (B-C)'!$B$8 -> 9632521.1 | D16: =C16/C15-1 -> 0.094721978
A17: 1998 | B17: C | C17: ='PBG por tramo'!E38*'Coeficiente de empalme (B-C)'!$B$8 -> 10262366 | D17: =C17/C16-1 -> 0.065387283
A18: 1999 | B18: C | C18: ='PBG por tramo'!E39*'Coeficiente de empalme (B-C)'!$B$8 -> 10007458 | D18: =C18/C17-1 -> -0.024839103
A19: 2000 | B19: C | C19: ='PBG por tramo'!E40*'Coeficiente de empalme (B-C)'!$B$8 -> 9736438.4 | D19: =C19/C18-1 -> -0.027081718
A20: 2001 | B20: C | C20: ='PBG por tramo'!E41*'Coeficiente de empalme (B-C)'!$B$8 -> 9001995.9 | D20: =C20/C19-1 -> -0.075432354
A21: 2002 | B21: C | C21: ='PBG por tramo'!E42*'Coeficiente de empalme (B-C)'!$B$8 -> 8406265.7 | D21: =C21/C20-1 -> -0.066177567
A22: 2003 | B22: C | C22: ='PBG por tramo'!E43*'Coeficiente de empalme (B-C)'!$B$8 -> 10101895 | D22: =C22/C21-1 -> 0.20171019
A23: 2004 | B23: D | C23: ='PBG por tramo'!E45*'Coeficiente de empalme (B-C)'!$B$8 -> 11762122 | D23: =C23/C22-1 -> 0.16434808
A24: 2005 | B24: D | C24: ='PBG por tramo'!E46*'Coeficiente de empalme (B-C)'!$B$8 -> 12309223 | D24: =C24/C23-1 -> 0.046513803
A25: 2006 | B25: D | C25: ='PBG por tramo'!E47*'Coeficiente de empalme (B-C)'!$B$8 -> 13259437 | D25: =C25/C24-1 -> 0.077195223
A26: 2007 | B26: D | C26: ='PBG por tramo'!E48*'Coeficiente de empalme (B-C)'!$B$8 -> 13812573 | D26: =C26/C25-1 -> 0.04171645
A27: 2008 | B27: D | C27: ='PBG por tramo'!E49*'Coeficiente de empalme (B-C)'!$B$8 -> 14131051 | D27: =C27/C26-1 -> 0.02305707
A28: 2009 | B28: D | C28: ='PBG por tramo'!E50*'Coeficiente de empalme (B-C)'!$B$8 -> 13736909 | D28: =C28/C27-1 -> -0.027891879
A29: 2010 | B29: D | C29: ='PBG por tramo'!E51*'Coeficiente de empalme (B-C)'!$B$8 -> 14344401 | D29: =C29/C28-1 -> 0.044223332
A30: 2011 | B30: D | C30: ='PBG por tramo'!E52*'Coeficiente de empalme (B-C)'!$B$8 -> 14860480 | D30: =C30/C29-1 -> 0.035977714
A31: 2012 | B31: D | C31: ='PBG por tramo'!E53*'Coeficiente de empalme (B-C)'!$B$8 -> 14650114 | D31: =C31/C30-1 -> -0.014156038
A32: 2013 | B32: D | C32: ='PBG por tramo'!E54*'Coeficiente de empalme (B-C)'!$B$8 -> 15370910 | D32: =C32/C31-1 -> 0.049200721
A33: 2014 | B33: D | C33: ='PBG por tramo'!E55*'Coeficiente de empalme (B-C)'!$B$8 -> 14804606 | D33: =C33/C32-1 -> -0.03684263
A34: 2015 | B34: D | C34: ='PBG por tramo'!E56*'Coeficiente de empalme (B-C)'!$B$8 -> 15347104 | D34: =C34/C33-1 -> 0.036643876
... A41: 2022 | B41: D | C41: ='PBG por tramo'!E63*'Coeficiente de empalme (B-C)'!$B$8 -> 15335414 | D41: =C41/C40-1 -> 0.039807221
