Workbook

Sheet Notas
A1: Producto Bruto Geográfico de Mendoza, 1970-2022
A3: Fuente original | B3: DEIE Mendoza — planilla 'PBG_1970-2022_variacionytasa_DEIE.xls'.
A4: Tramos | B4: Los datos se publicaron en 4 tramos, cada uno a precios constantes de un año base distinto:
A5: 1970-1985 | B5: A valores constantes de 1970, en Australes.
A6: 1986-1993 | B6: En pesos de 1996 (año base 1996, según la propia planilla de la DEIE).
A7: 1991-2003 | B7: En miles de pesos de 1993.
A8: 2004-2022 | B8: En miles de pesos de 1993
A9: Empalme B->C | B9: Los tramos 1986-1993 y 1991-2003 SÍ se solapan en 1991-1993. Se usó el coeficiente de 1993 (año base del tramo largo) para reexpresar 1986-1990 en miles de pesos de 1993.
A10: Empalme A->B | B10: No hay año de solapamiento entre 1970-1985 y 1986-1993. Se probó primero la tabla oficial de conversión monetaria (Austral->Peso) + IPC, y dio un salto de nivel de aprox 30.000 veces frente al tramo siguiente, osea que el cambio de año base implica un recálculo metodológico, no solo cambio de moneda y precios. Se resolvió usando el PBI nacional (Ferreres) como proxy del crecimiento real de Mendoza en 1986, para despejar el coeficiente de empalme implícito (ver hoja 'Coeficiente de empalme (A-B)'). Ese coeficiente combina moneda + metodología: no aísla el tipo de cambio Austral-Peso por sí solo.
A11: Base 1999 | B11: Toda la serie empalmada (miles de $ de 1993) se reexpresó a precios de 1999 multiplicando por IPC(1999)/IPC(1993), usando el IPC INDEC nivel general, base 1999=100.
A12: Quiebre 2003-2004 | B12: Según La DEIE, no hay registro del empalme formal entre las mediciones 1991-2003 y 2004-2022, que hubo un cambio metodológico en la forma de medir el pbg. Se dejaron como continuas por ser la única fuente disponible; el salto de +16,4% en 2004 refleja esto mismo, no un error.
A13: Hoja 'PBG índice 1970-1985' | B13: Queda como referencia del enfoque anterior (índice sin empalmar). La hoja 'PBG a precios de 1999' es la serie recomendada: ya incluye todo 1970-2022 en una sola unidad monetaria.

Sheet PBG por tramo
A1: Producto Bruto Geográfico de Mendoza — series por tramo de publicación
A2: Fuente: DEIE Mendoza y P. Olguín. Cada tramo está a precios constantes del año base indicado (ver hoja Notas).
A4: Año | B4: Tramo | C4: Moneda / unidad | D4: Precios constantes de | E4: PBG | F4: Variación anual (%)
A5: 1970 | B5: 1970-1985 | C5: Australes | D5: 1970 | E5: 313.43
A6: 1971 | B6: 1970-1985 | C6: Australes | D6: 1970 | E6: 334.41 | F6: =E6/E5-1 -> 0.066936796
A7: 1972 | B7: 1970-1985 | C7: Australes | D7: 1970 | E7: 356.26 | F7: =E7/E6-1 -> 0.065338955
A8: 1973 | B8: 1970-1985 | C8: Australes | D8: 1970 | E8: 364.33 | F8: =E8/E7-1 -> 0.022651996
A9: 1974 | B9: 1970-1985 | C9: Australes | D9: 1970 | E9: 406.37 | F9: =E9/E8-1 -> 0.11538989
A10: 1975 | B10: 1970-1985 | C10: Australes | D10: 1970 | E10: 355.2 | F10: =E10/E9-1 -> -0.12591973
A11: 1976 | B11: 1970-1985 | C11: Australes | D11: 1970 | E11: 404.05 | F11: =E11/E10-1 -> 0.13752815
A12: 1977 | B12: 1970-1985 | C12: Australes | D12: 1970 | E12: 380.63 | F12: =E12/E11-1 -> -0.057963123
A13: 1978 | B13: 1970-1985 | C13: Australes | D13: 1970 | E13: 423.6 | F13: =E13/E12-1 -> 0.11289178
A14: 1979 | B14: 1970-1985 | C14: Australes | D14: 1970 | E14: 481.05 | F14: =E14/E13-1 -> 0.13562323
A15: 1980 | B15: 1970-1985 | C15: Australes | D15: 1970 | E15: 429.24 | F15: =E15/E14-1 -> -0.1077019
A16: 1981 | B16: 1970-1985 | C16: Australes | D16: 1970 | E16: 351.83 | F16: =E16/E15-1 -> -0.180342
A17: 1982 | B17: 1970-1985 | C17: Australes | D17: 1970 | E17: 360.43 | F17: =E17/E16-1 -> 0.024443623
... A20: 1985 | B20: 1970-1985 | C20: Australes | D20: 1970 | E20: 384.61 | F20: =E20/E19-1 -> -0.049030759
A22: 1986 | B22: 1986-1993 | C22: Pesos | D22: 1996 | E22: 267608.7
A23: 1987 | B23: 1986-1993 | C23: Pesos | D23: 1996 | E23: 271052 | F23: =E23/E22-1 -> 0.012866921
A24: 1988 | B24: 1986-1993 | C24: Pesos | D24: 1996 | E24: 264473 | F24: =E24/E23-1 -> -0.024272095
A25: 1989 | B25: 1986-1993 | C25: Pesos | D25: 1996 | E25: 253410 | F25: =E25/E24-1 -> -0.041830357
A26: 1990 | B26: 1986-1993 | C26: Pesos | D26: 1996 | E26: 253627 | F26: =E26/E25-1 -> 0.0008563198
A27: 1991 | B27: 1986-1993 | C27: Pesos | D27: 1996 | E27: 259579 | F27: =E27/E26-1 -> 0.023467533
A28: 1992 | B28: 1986-1993 | C28: Pesos | D28: 1996 | E28: 277469 | F28: =E28/E27-1 -> 0.068919289
A29: 1993 | B29: 1986-1993 | C29: Pesos | D29: 1996 | E29: 296965 | F29: =E29/E28-1 -> 0.070263705
A31: 1991 | B31: 1991-2003 | C31: Miles de pesos | D31: 1993 | E31: 6485506.9
A32: 1992 | B32: 1991-2003 | C32: Miles de pesos | D32: 1993 | E32: 7035025.6 | F32: =E32/E31-1 -> 0.084730252
A33: 1993 | B33: 1991-2003 | C33: Miles de pesos | D33: 1993 | E33: 7761508.2 | F33: =E33/E32-1 -> 0.10326652
A34: 1994 | B34: 1991-2003 | C34: Miles de pesos | D34: 1993 | E34: 8098028.3 | F34: =E34/E33-1 -> 0.043357564
A35: 1995 | B35: 1991-2003 | C35: Miles de pesos | D35: 1993 | E35: 7908811.4 | F35: =E35/E34-1 -> -0.023365802
A36: 1996 | B36: 1991-2003 | C36: Miles de pesos | D36: 1993 | E36: 8135361.9 | F36: =E36/E35-1 -> 0.028645327
A37: 1997 | B37: 1991-2003 | C37: Miles de pesos | D37: 1993 | E37: 8905959.4 | F37: =E37/E36-1 -> 0.094721978
A38: 1998 | B38: 1991-2003 | C38: Miles de pesos | D38: 1993 | E38: 9488295.9 | F38: =E38/E37-1 -> 0.065387283
A39: 1999 | B39: 1991-2003 | C39: Miles de pesos | D39: 1993 | E39: 9252615.2 | F39: =E39/E38-1 -> -0.024839103
A40: 2000 | B40: 1991-2003 | C40: Miles de pesos | D40: 1993 | E40: 9002038.5 | F40: =E40/E39-1 -> -0.027081718
A41: 2001 | B41: 1991-2003 | C41: Miles de pesos | D41: 1993 | E41: 8322993.5 | F41: =E41/E40-1 -> -0.075432354
A42: 2002 | B42: 1991-2003 | C42: Miles de pesos | D42: 1993 | E42: 7772198 | F42: =E42/E41-1 -> -0.066177567
A43: 2003 | B43: 1991-2003 | C43: Miles de pesos | D43: 1993 | E43: 9339929.6 | F43: =E43/E42-1 -> 0.20171019
A45: 2004 | B45: 2004-2022 | C45: Miles de pesos | D45: 1993 | E45: 10874929
A46: 2005 | B46: 2004-2022 | C46: Miles de pesos | D46: 1993 | E46: 11380763 | F46: =E46/E45-1 -> 0.046513803
...

Sheet IPC INDEC
A1: IPC INDEC — Nivel general, base 1999=100
A3: Año | B3: IPC (base 1999=100)
A4: 1970 | B4: 4.7536083e-10
A5: 1971 | B5: 6.4042e-10
A6: 1972 | B6: 1.0147767e-09
A7: 1973 | B7: 1.6267208e-09
A8: 1974 | B8: 2.0206542e-09
A9: 1975 | B9: 5.7142667e-09
A10: 1976 | B10: 3.10863e-08
A11: 1977 | B11: 8.580805e-08
A12: 1978 | B12: 2.3640875e-07
A13: 1979 | B13: 6.1350683e-07
A14: 1980 | B14: 1.231702e-06
A15: 1981 | B15: 2.51855e-06
... A55: 2021 | B55: 8136.2593

Sheet Coeficiente de empalme (B-C)
A1: Coeficiente de empalme 1986-1993 -> 1991-2003
A3: Usa el solapamiento real 1991-1993 (ancla en 1993, año base del tramo largo).
A5: Coef_B | B5: ='PBG por tramo'!E33/'PBG por tramo'!E29 -> 26.136104
A7: Factor de reexpresión a precios de 1999 (IPC INDEC)
A8: Factor_1999 | B8: ='IPC INDEC'!B33/'IPC INDEC'!B27 -> 1.0815815
A10: Nota
A11: El tramo 1970-1985 NO se empalma con este: no hay año de solapamiento con 1986-1993, y se comprobó que usar la tabla de conversión monetaria (Austral->Peso) junto con el IPC da un salto de nivel de ~30.000 veces, incompatible con la evolución real observada. Ver hoja 'PBG índice 1970-1985'.

Sheet PBI Ferreres (nacional)
A1: PBI nacional a precios de mercado — Base Ferreres (mill. de $ de 1993)
A2: Fuente: Ferreres. Se usa como fuente de crecimiento real para el empalme 1985-1986 (sin año de solapamiento en el PBG de Mendoza).
A4: Año | B4: PBI (mill. $ de 1993)
A5: 1969 | B5: 152643.77
A6: 1970 | B6: 160860.96
A7: 1971 | B7: 166912.61
A8: 1972 | B8: 170379.33
A9: 1973 | B9: 176760.97
A10: 1974 | B10: 186316.02
A11: 1975 | B11: 185210.55
A12: 1976 | B12: 185188.55
A13: 1977 | B13: 197015.03
A14: 1978 | B14: 190666.39
A15: 1979 | B15: 203891.65
A16: 1980 | B16: 207011.43
... A40: 2004 | B40: 279020

Sheet Coeficiente de empalme (A-B)
A1: Coeficiente de empalme 1970-1985 -> 1986-1993
A3: Sin año de solapamiento entre tramos. Se usa el crecimiento real del PBI nacional (Ferreres) de 1986 como fuente del crecimiento real de Mendoza ese año, para despejar el coeficiente que hace empalmar los dos tramos.
A5: g_1986 (crecimiento real, proxy PBI nacional) | B5: ='PBI Ferreres (nacional)'!B22/'PBI Ferreres (nacional)'!B21-1 -> 0.071386437
A7: K (moneda + rebase, implícito) | B7: ='PBG por tramo'!E22/('PBG por tramo'!E20*(1+B5)) -> 649.43174
A9: Nota
A10: K NO es un factor de conversión monetaria puro: incluye también el recálculo metodológico de la DEIE al cambiar de año base (ver hoja 'Coeficiente de empalme (B-C)' para una comparación de magnitudes). Sirve para reconstruir la serie continua, no para aislar el tipo de cambio Austral-Peso.

Sheet PBG a precios de 1999
A1: PBG Mendoza, 1970-2022 — serie única, a precios constantes de 1999
A2: 1970-1985 empalmado con el PBI nacional (Ferreres) como fuente de crecimiento real en 1986 (sin año de solapamiento). 1986-2022 empalmado con años de solapamiento reales (1991-1993).
A4: Año | B4: Tramo de origen | C4: PBG (miles $ ctes. de 1999) | D4: Variación anual (%)
A5: 1970 | B5: A | C5: ='PBG por tramo'!E5*'Coeficiente de empalme (A-B)'!$B$7*'Coeficiente de empalme (B-C)'!$B$5*'Coeficiente de empalme (B-C)'!$B$8 -> 5754057.4
A6: 1971 | B6: A | C6: ='PBG por tramo'!E6*'Coeficiente de empalme (A-B)'!$B$7*'Coeficiente de empalme (B-C)'!$B$5*'Coeficiente de empalme (B-C)'!$B$8 -> 6139215.5 | D6: =C6/C5-1 -> 0.066936796
A7: 1972 | B7: A | C7: ='PBG por tramo'!E7*'Coeficiente de empalme (A-B)'!$B$7*'Coeficiente de empalme (B-C)'!$B$5*'Coeficiente de empalme (B-C)'!$B$8 -> 6540345.5 | D7: =C7/C6-1 -> 0.065338955
A8: 1973 | B8: A | C8: ='PBG por tramo'!E8*'Coeficiente de empalme (A-B)'!$B$7*'Coeficiente de empalme (B-C)'!$B$5*'Coeficiente de empalme (B-C)'!$B$8 -> 6688497.3 | D8: =C8/C7-1 -> 0.022651996
A9: 1974 | B9: A | C9: ='PBG por tramo'!E9*'Coeficiente de empalme (A-B)'!$B$7*'Coeficiente de empalme (B-C)'!$B$5*'Coeficiente de empalme (B-C)'!$B$8 -> 7460282.3 | D9: =C9/C8-1 -> 0.11538989
A10: 1975 | B10: A | C10: ='PBG por tramo'!E10*'Coeficiente de empalme (A-B)'!$B$7*'Coeficiente de empalme (B-C)'!$B$5*'Coeficiente de empalme (B-C)'!$B$8 -> 6520885.6 | D10: =C10/C9-1 -> -0.12591973
A11: 1976 | B11: A | C11: ='PBG por tramo'!E11*'Coeficiente de empalme (A-B)'!$B$7*'Coeficiente de empalme (B-C)'!$B$5*'Coeficiente de empalme (B-C)'!$B$8 -> 7417691 | D11: =C11/C10-1 -> 0.13752815
A12: 1977 | B12: A | C12: ='PBG por tramo'!E12*'Coeficiente de empalme (A-B)'!$B$7*'Coeficiente de empalme (B-C)'!$B$5*'Coeficiente de empalme (B-C)'!$B$8 -> 6987738.4 | D12: =C12/C11-1 -> -0.057963123
A13: 1978 | B13: A | C13: ='PBG por tramo'!E13*'Coeficiente de empalme (A-B)'!$B$7*'Coeficiente de empalme (B-C)'!$B$5*'Coeficiente de empalme (B-C)'!$B$8 -> 7776596.7 | D13: =C13/C12-1 -> 0.11289178
A14: 1979 | B14: A | C14: ='PBG por tramo'!E14*'Coeficiente de empalme (A-B)'!$B$7*'Coeficiente de empalme (B-C)'!$B$5*'Coeficiente de empalme (B-C)'!$B$8 -> 8831283.8 | D14: =C14/C13-1 -> 0.13562323
A15: 1980 | B15: A | C15: ='PBG por tramo'!E15*'Coeficiente de empalme (A-B)'!$B$7*'Coeficiente de empalme (B-C)'!$B$5*'Coeficiente de empalme (B-C)'!$B$8 -> 7880137.8 | D15: =C15/C14-1 -> -0.1077019
A16: 1981 | B16: A | C16: ='PBG por tramo'!E16*'Coeficiente de empalme (A-B)'!$B$7*'Coeficiente de empalme (B-C)'!$B$5*'Coeficiente de empalme (B-C)'!$B$8 -> 6459018 | D16: =C16/C15-1 -> -0.180342
A17: 1982 | B17: A | C17: ='PBG por tramo'!E17*'Coeficiente de empalme (A-B)'!$B$7*'Coeficiente de empalme (B-C)'!$B$5*'Coeficiente de empalme (B-C)'!$B$8 -> 6616899.8 | D17: =C17/C16-1 -> 0.024443623
... A20: 1985 | B20: A | C20: ='PBG por tramo'!E20*'Coeficiente de empalme (A-B)'!$B$7*'Coeficiente de empalme (B-C)'!$B$5*'Coeficiente de empalme (B-C)'!$B$8 -> 7060804.7 | D20: =C20/C19-1 -> -0.049030759
A21: 1986 | B21: B | C21: ='PBG por tramo'!E22*'Coeficiente de empalme (B-C)'!$B$5*'Coeficiente de empalme (B-C)'!$B$8 -> 7564850.3 | D21: =C21/C20-1 -> 0.071386437
A22: 1987 | B22: B | C22: ='PBG por tramo'!E23*'Coeficiente de empalme (B-C)'!$B$5*'Coeficiente de empalme (B-C)'!$B$8 -> 7662186.7 | D22: =C22/C21-1 -> 0.012866921
A23: 1988 | B23: B | C23: ='PBG por tramo'!E24*'Coeficiente de empalme (B-C)'!$B$5*'Coeficiente de empalme (B-C)'!$B$8 -> 7476209.3 | D23: =C23/C22-1 -> -0.024272095
A24: 1989 | B24: B | C24: ='PBG por tramo'!E25*'Coeficiente de empalme (B-C)'!$B$5*'Coeficiente de empalme (B-C)'!$B$8 -> 7163476.8 | D24: =C24/C23-1 -> -0.041830357
A25: 1990 | B25: B | C25: ='PBG por tramo'!E26*'Coeficiente de empalme (B-C)'!$B$5*'Coeficiente de empalme (B-C)'!$B$8 -> 7169611.1 | D25: =C25/C24-1 -> 0.0008563198
A26: 1991 | B26: C | C26: ='PBG por tramo'!E31*'Coeficiente de empalme (B-C)'!$B$8 -> 7014604.4 | D26: =C26/C25-1 -> -0.021619949
A27: 1992 | B27: C | C27: ='PBG por tramo'!E32*'Coeficiente de empalme (B-C)'!$B$8 -> 7608953.6 | D27: =C27/C26-1 -> 0.084730252
A28: 1993 | B28: C | C28: ='PBG por tramo'!E33*'Coeficiente de empalme (B-C)'!$B$8 -> 8394703.8 | D28: =C28/C27-1 -> 0.10326652
A29: 1994 | B29: C | C29: ='PBG por tramo'!E34*'Coeficiente de empalme (B-C)'!$B$8 -> 8758677.7 | D29: =C29/C28-1 -> 0.043357564
A30: 1995 | B30: C | C30: ='PBG por tramo'!E35*'Coeficiente de empalme (B-C)'!$B$8 -> 8554024.2 | D30: =C30/C29-1 -> -0.023365802
A31: 1996 | B31: C | C31: ='PBG por tramo'!E36*'Coeficiente de empalme (B-C)'!$B$8 -> 8799057 | D31: =C31/C30-1 -> 0.028645327
A32: 1997 | B32: C | C32: ='PBG por tramo'!E37*'Coeficiente de empalme (B-C)'!$B$8 -> 9632521.1 | D32: =C32/C31-1 -> 0.094721978
A33: 1998 | B33: C | C33: ='PBG por tramo'!E38*'Coeficiente de empalme (B-C)'!$B$8 -> 10262366 | D33: =C33/C32-1 -> 0.065387283
A34: 1999 | B34: C | C34: ='PBG por tramo'!E39*'Coeficiente de empalme (B-C)'!$B$8 -> 10007458 | D34: =C34/C33-1 -> -0.024839103
A35: 2000 | B35: C | C35: ='PBG por tramo'!E40*'Coeficiente de empalme (B-C)'!$B$8 -> 9736438.4 | D35: =C35/C34-1 -> -0.027081718
A36: 2001 | B36: C | C36: ='PBG por tramo'!E41*'Coeficiente de empalme (B-C)'!$B$8 -> 9001995.9 | D36: =C36/C35-1 -> -0.075432354
A37: 2002 | B37: C | C37: ='PBG por tramo'!E42*'Coeficiente de empalme (B-C)'!$B$8 -> 8406265.7 | D37: =C37/C36-1 -> -0.066177567
A38: 2003 | B38: C | C38: ='PBG por tramo'!E43*'Coeficiente de empalme (B-C)'!$B$8 -> 10101895 | D38: =C38/C37-1 -> 0.20171019
A39: 2004 | B39: D | C39: ='PBG por tramo'!E45*'Coeficiente de empalme (B-C)'!$B$8 -> 11762122 | D39: =C39/C38-1 -> 0.16434808
A40: 2005 | B40: D | C40: ='PBG por tramo'!E46*'Coeficiente de empalme (B-C)'!$B$8 -> 12309223 | D40: =C40/C39-1 -> 0.046513803
A41: 2006 | B41: D | C41: ='PBG por tramo'!E47*'Coeficiente de empalme (B-C)'!$B$8 -> 13259437 | D41: =C41/C40-1 -> 0.077195223
A42: 2007 | B42: D | C42: ='PBG por tramo'!E48*'Coeficiente de empalme (B-C)'!$B$8 -> 13812573 | D42: =C42/C41-1 -> 0.04171645
A43: 2008 | B43: D | C43: ='PBG por tramo'!E49*'Coeficiente de empalme (B-C)'!$B$8 -> 14131051 | D43: =C43/C42-1 -> 0.02305707
...
